Workbook
Name A._BẢO_DƯỠNG_THƯỜNG_XUYÊN_TÀI_SẢN_KCHTHK_DO_NHÀ_NƯỚC_ĐẦU_TƯ__QUẢN_LÝ: 'TỔNG HỢP'!#REF!
Name A._BẢO_DƯỠNG_THƯỜNG_XUYÊN_TÀI_SẢN_KCHTHK_DO_NHÀ_NƯỚC_ĐẦU_TƯ__QUẢN_LÝ: #REF!
Name B._BẢO_TRÌ_TTB_PHỤC_VỤ_CHO_HOẠT_ĐỘNG_KHAI_THÁC_TÀI_SẢN_KCHTHK__Tài_sản_Nhà_nước: 'TỔNG HỢP'!#REF!
Name B._BẢO_TRÌ_TTB_PHỤC_VỤ_CHO_HOẠT_ĐỘNG_KHAI_THÁC_TÀI_SẢN_KCHTHK__Tài_sản_Nhà_nước: #REF!
Name Chi_phí_cắt_cỏ__nạo_vét_mương_thoát_nước: 'TỔNG HỢP'!$B$7
Name Chi_phí_cắt_cỏ__nạo_vét_mương_thoát_nước: #REF!
Name Chi_phí_sửa_chữa_mương_thoát_nước: 'TỔNG HỢP'!$B$6
Name Chi_phí_sửa_chữa_mương_thoát_nước: #REF!
Name SCTX_MÁY_MÓC_THIẾT_BỊ: 'TỔNG HỢP'!$B$12
Name SCTX_MÁY_MÓC_THIẾT_BỊ: #REF!
Name Sửa_chữa_bến_bãi_ô_tô__sân_đường: 'TỔNG HỢP'!$B$5
Name Sửa_chữa_bến_bãi_ô_tô__sân_đường: #REF!
Name Sửa_chữa_hàng_rào: 'TỔNG HỢP'!$B$9
Name Sửa_chữa_hàng_rào: #REF!
Name Sửa_chữa_hệ_thống_băng_chuyền: 'TỔNG HỢP'!$B$13
Name Sửa_chữa_hệ_thống_băng_chuyền: #REF!
Name Sửa_chữa_hệ_thống_camera__CCTV: 'TỔNG HỢP'!$B$29
Name Sửa_chữa_hệ_thống_camera__CCTV: #REF!
Name Sửa_chữa_hệ_thống_cấp_nước: 'TỔNG HỢP'!$B$25
Name Sửa_chữa_hệ_thống_cấp_nước: #REF!
Name Sửa_chữa_hệ_thống_máy_móc__thiết_bị_làm_thủ_tục: 'TỔNG HỢP'!$B$18
Name Sửa_chữa_hệ_thống_máy_móc__thiết_bị_làm_thủ_tục: #REF!
Name Sửa_chữa_hệ_thống_ống_lồng: 'TỔNG HỢP'!$B$14
Name Sửa_chữa_hệ_thống_ống_lồng: #REF!
Name Sửa_chữa_hệ_thống_quầy_thủ_tục__thiết_bị_nội_thất: 'TỔNG HỢP'!$B$17
Name Sửa_chữa_hệ_thống_quầy_thủ_tục__thiết_bị_nội_thất: #REF!
Name Sửa_chữa_hệ_thống_thang_cuốn__thang_máy: 'TỔNG HỢP'!$B$15
Name Sửa_chữa_hệ_thống_thang_cuốn__thang_máy: #REF!
Name Sửa_chữa_hệ_thống_thiết_bị_phục_vụ_máy_bay: 'TỔNG HỢP'!$B$28
Name Sửa_chữa_hệ_thống_thiết_bị_phục_vụ_máy_bay: #REF!
Name Sửa_chữa_hệ_thống_thiết_bị_vệ_sinh: 'TỔNG HỢP'!$B$19
Name Sửa_chữa_hệ_thống_thiết_bị_vệ_sinh: #REF!
Name Sửa_chữa_hệ_thống_thoát_nước: 'TỔNG HỢP'!$B$26
Name Sửa_chữa_hệ_thống_thoát_nước: #REF!
Name Sửa_chữa_hệ_thống_thông_tin_liên_lạc: 'TỔNG HỢP'!$B$16
Name Sửa_chữa_hệ_thống_thông_tin_liên_lạc: #REF!
Name Sửa_chữa_hệ_thống_trạm_thu_phí: 'TỔNG HỢP'!$B$27
Name Sửa_chữa_hệ_thống_trạm_thu_phí: #REF!
Name Sửa_chữa_hệ_thống_xử_lý_chất_thải: 'TỔNG HỢP'!$B$24
Name Sửa_chữa_hệ_thống_xử_lý_chất_thải: #REF!
Name Sửa_chữa_máy_móc__thiết_bị___hệ_thống_thiết_bị_điện: 'TỔNG HỢP'!$B$21
Name Sửa_chữa_máy_móc__thiết_bị___hệ_thống_thiết_bị_điện: #REF!
Name Sửa_chữa_máy_móc__thiết_bị___hệ_thống_thiết_bị_lạnh: 'TỔNG HỢP'!$B$22
Name Sửa_chữa_máy_móc__thiết_bị___hệ_thống_thiết_bị_lạnh: #REF!
Name Sửa_chữa_máy_móc_thiết_bị_kiểm_tra_an_ninh: 'TỔNG HỢP'!$B$20
Name Sửa_chữa_máy_móc_thiết_bị_kiểm_tra_an_ninh: #REF!
Name Sửa_chữa_máy_móc_thiết_bị_khác: 'TỔNG HỢP'!$B$30
Name Sửa_chữa_máy_móc_thiết_bị_khác: #REF!
Name Sửa_chữa_nhà_cửa__vật_kiến_trúc_khác: 'TỔNG HỢP'!$B$10
Name Sửa_chữa_nhà_cửa__vật_kiến_trúc_khác: #REF!
Name Sửa_chữa_nhà_ga_quốc_nội: #REF!
Name Sửa_chữa_phương_tiện_vận_tải_đặc_chủng_phục_vụ_bay: 'TỔNG HỢP'!$B$32
Name Sửa_chữa_phương_tiện_vận_tải_đặc_chủng_phục_vụ_bay: #REF!
Name Sửa_chữa_phương_tiện_vận_tải_khác: 'TỔNG HỢP'!$B$36
Name Sửa_chữa_phương_tiện_vận_tải_khác: #REF!
Name Sửa_chữa_thiết_bị_PCCC: 'TỔNG HỢP'!$B$23
Name Sửa_chữa_thiết_bị_PCCC: #REF!
Name Sửa_chữa_xe_cứu_hỏa__cứu_thương__xe_chuyên_dùng: 'TỔNG HỢP'!$B$33
Name Sửa_chữa_xe_cứu_hỏa__cứu_thương__xe_chuyên_dùng: #REF!
Name Sửa_chữa_xe_ô_tô__khối_gián_tiếp: 'TỔNG HỢP'!$B$35

Sheet INFO
A1: NƠI NHẬP DỮ TIỆU TỪ PHẦN MỀM KẾ TOÁN BRAVO ĐỂ SO SÁNH
D2: Giá trị | E2: Tỷ lệ | F2: Giá trị | G2: Tỷ lệ | H2: Chi phí sản xuất kinh doanh
A3: Chi phí sản xuất kinh doanh | C3: 138892000000 | D3: 122874800784 | E3: 0.88467875 | F3: 122874800784 | G3: 0.88467875 | H3: Chi phí nhân viên
A4: Chi phí nhân viên | C4: 7349000000 | D4: 35334505031 | E4: 4.8080698 | F4: 35334505031 | G4: 4.8080698 | H4: Chi phí tiền lương
A5: Chi phí tiền lương | B5: 62711 | C5: 0 | D5: 30245273915 | E5: 0 | F5: 30245273915 | G5: 0 | H5: Thưởng an toàn hàng không
A6: Phụ cấp đội PCCC cơ sở | B6: 627121 | C6: 0 | E6: 0 | G6: 0 | H6: Tiền ăn giữa ca
A7: Phụ cấp an toàn, vệ sinh viên | B7: 627122 | C7: 26000000 | D7: 17028000 | E7: 0.6549 | F7: 17028000 | G7: 0.6549 | H7: Kinh phí công đoàn
A8: Tiền ăn giữa ca | B8: 62713 | C8: 3208000000 | D8: 1995540000 | E8: 0.6221 | F8: 1995540000 | G8: 0.6221 | H8: Chi phí bảo hiểm xã hội
A9: Kinh phí công đoàn | B9: 62714 | C9: 323000000 | D9: 261355318 | E9: 0.8091 | F9: 261355318 | G9: 0.8091 | H9: Chi phí bảo hiểm y tế
A10: Chi phí bảo hiểm xã hội | B10: 62715 | C10: 3086000000 | D10: 2292390622 | E10: 0.7428 | F10: 2292390622 | G10: 0.7428 | H10: Chi phí bảo hiểm thất nghiệp
A11: Chi phí bảo hiểm y tế | B11: 62716 | C11: 529000000 | D11: 392239517 | E11: 0.7415 | F11: 392239517 | G11: 0.7415 | H11: Chi phí nguyên, vật liệu
A12: Chi phí bảo hiểm thất nghiệp | B12: 62717 | C12: 177000000 | D12: 130677659 | E12: 0.7383 | F12: 130677659 | G12: 0.7383 | H12: Chi phí nhiên liệu
A13: Chi phí nguyên, vật liệu | C13: 1231000000 | D13: 1231090374 | E13: 1.0000734 | F13: 1231090374 | G13: 1.0000734 | H13: Vật tư vệ sinh
A14: Chi phí nhiên liệu | B14: 62721 | C14: 800000000 | D14: 916253686 | E14: 1.1453 | F14: 916253686 | G14: 1.1453 | H14: Vật tư, tem, nhãn kiểm tra an ninh hàng không
A15: Vật tư vệ sinh | B15: 62722 | C15: 150000000 | D15: 157182286 | E15: 1.0479 | F15: 157182286 | G15: 1.0479 | H15: Vật liệu phục vụ chuyến bay
A16: Vật tư, tem, nhãn kiểm tra an ninh hàng không | B16: 62723 | C16: 20000000 | E16: 0 | G16: 0 | H16: Vật liệu xử lý chất thải, hóa chất hệ thống lạnh
A17: Vật liệu phục vụ chuyến bay | B17: 62724 | C17: 40000000 | D17: 27714000 | E17: 0.6929 | F17: 27714000 | G17: 0.6929 | H17: Vật tư in ấn vé sân đường, hóa đơn
A18: Vật liệu xử lý chất thải, hóa chất hệ thống lạnh | B18: 62725 | C18: 126000000 | D18: 87955140 | E18: 0.6981 | F18: 87955140 | G18: 0.6981 | H18: Chi phí nhiên liệu phục vụ công tác
A19: Vật tư in ấn vé sân đường, hóa đơn | B19: 62726 | C19: 20000000 | D19: 10249999 | E19: 0.5125 | F19: 10249999 | G19: 0.5125 | H19: Chi phí vật liệu khác
A20: Chi phí nhiên liệu phục vụ công tác | B20: 62727 | C20: 75000000 | D20: 31735263 | E20: 0.4231 | F20: 31735263 | G20: 0.4231 | H20: Chi phí dụng cụ sản xuất
A21: Chi phí dụng cụ sản xuất | C21: 1089000000 | D21: 605563865 | E21: 0.55607334 | F21: 605563865 | G21: 0.55607334 | H21: Chi phí mua sắm công cụ dụng cụ
A22: Chi phí mua sắm công cụ dụng cụ | C22: 863000000 | D22: 595714878 | E22: 0.69028375 | F22: 595714878 | G22: 0.69028375 | H22: Công cụ dụng cụ lao động
A23: Công cụ dụng cụ lao động | B23: 627311 | C23: 610000000 | D23: 411772493 | E23: 0.675 | F23: 411772493 | G23: 0.675 | H23: Trang thiết bị văn phòng
A24: Trang thiết bị văn phòng | B24: 627312 | C24: 73000000 | D24: 122391542 | E24: 1.6766 | F24: 122391542 | G24: 1.6766 | H24: Trang thiết bị và bảng biểu nhà ga
A25: Trang thiết bị và bảng biểu nhà ga | B25: 627313 | C25: 100000000 | E25: 0 | G25: 0 | H25: Bàn ghế, tủ, quầy ,vật dụng khác
A26: Bàn ghế, tủ, quầy ,vật dụng khác | B26: 627314 | C26: 80000000 | D26: 61550843 | E26: 0.7694 | F26: 61550843 | G26: 0.7694 | H26: Chi phí sửa chữa công cụ dụng cụ
A27: Chi phí sửa chữa công cụ dụng cụ | C27: 226000000 | D27: 9848987 | E27: 0.043579588 | F27: 9848987 | G27: 0.043579588 | H27: Chi phí sửa chữa công cụ dụng cụ
A28: Chi phí sửa chữa công cụ dụng cụ | B28: 627321 | C28: 196000000 | D28: 5697139 | E28: 0.0291 | F28: 5697139 | G28: 0.0291 | H28: Chi phí sửa chữa công cụ dụng cụ (khối gián tiếp)
A29: Chi phí sửa chữa công cụ dụng cụ (khối gián tiếp) | B29: 627322 | C29: 30000000 | D29: 4151848 | E29: 0.1384 | F29: 4151848 | G29: 0.1384 | H29: Chi phí khấu hao TSCĐ
A30: Chi phí khấu hao TSCĐ | C30: 52229000000 | D30: 53683774716 | E30: 1.0278538 | F30: 53683774716 | G30: 1.0278538 | H30: Chi phí khấu hao TSCĐ
A31: Chi phí khấu hao TSCĐ | B31: 62741 | C31: 52229000000 | D31: 53683774716 | E31: 1.0279 | F31: 53683774716 | G31: 1.0279 | H31: Thuế, phí, và lệ phí
A32: Thuế, phí, và lệ phí | C32: 773000000 | D32: 386743680 | E32: 0.50031524 | F32: 386743680 | G32: 0.50031524 | H32: Thuế môn bài
A33: Thuế môn bài | B33: 62751 | C33: 0 | E33: 0 | G33: 0 | H33: Thuế đất và tiền thuê đất
A34: Thuế đất và tiền thuê đất | B34: 62752 | C34: 773000000 | D34: 386743680 | E34: 0.5003 | F34: 386743680 | G34: 0.5003 | H34: Thuế VAT không được khấu trừ
A35: Chi phí sửa chữa, bảo dưỡng tài sản | C35: 51698000000 | D35: 16488077086 | E35: 0.31893066 | F35: 16488077086 | G35: 0.31893066 | H35: Thuế khác
A36: Chi phí sửa chữa | C36: 45355000000 | D36: 16442561450 | E36: 0.36253029 | F36: 16442561450 | G36: 0.36253029 | H36: Chi phí sửa chữa tài sản
A37: Chi phí sửa chữa nhà cửa, vật kiến trúc | C37: 9999000000 | D37: 2667492579 | E37: 0.26677594 | F37: 2667492579 | G37: 0.26677594 | H37: Chi phí sửa chữa thường xuyên
A38: Sửa chữa nhà ga quốc nội | B38: 62762101 | C38: 2400000000 | D38: 102604899 | E38: 0.0428 | F38: 102604899 | G38: 0.0428 | H38: Chi phí SCTX nhà cửa, vật kiến trúc
A39: Sửa chữa bến bãi ô tô, sân đường | B39: 62762103 | C39: 3520000000 | D39: 2363496364 | E39: 0.6714 | F39: 2363496364 | G39: 0.6714 | H39: Sửa chữa nhà ga quốc nội
A40: Chi phí sửa chữa mương thoát nước | B40: 62762104 | C40: 69000000 | D40: 3240741 | E40: 0.047 | F40: 3240741 | G40: 0.047 | H40: Sửa chữa bến bãi ô tô, sân đưòng
...

Sheet Giao Bổ sung (2)
A1: TỔNG HỢP TRIỂN KHAI BỔ SUNG KẾ HOẠCH 2023
A2: STT | B2: Danh mục | C2: Mã khoản mục chi phí | D2: ĐƯỢC DUYỆT 2023 | E2: BỔ SUNG 2023 | F2: SỐ TIỀN ĐÃ/ ĐANG THỰC HIỆN | G2: TỔNG CÒN SAU BỔ SUNG | H2: QUY MÔ | I2: NGƯỜI THỰC HIỆN | J2: Tiến độ
A5: A | B5: ĐẦU TƯ CHUYỂN TIẾP
A6: A | B6: ĐẦU TƯ
A7: I | B7: XÂY DỰNG CƠ BẢN | C7: Column1 | D7: Column2 | E7: Column3 | F7: Column4 | G7: Column5 | H7: Column7
A8: II | B8: TRANG THIẾT BỊ | C8: Column1 | D8: Column2 | E8: Column3 | F8: Column4 | G8: Column5 | H8: Column7
A9: 1 | B9: Máy khắc Laser kim loại | E9: 60000000 | G9: =E9 -> 60000000 | H9: Máy khắc laser kim loại 20W | I9: Thanh Tân | L9: ĐÃ HOÀN THÀNH
A10: 2 | B10: Xe tải ben | E10: 700000000 | G10: =E10 -> 700000000 | H10: Xe tải ben 1.9T | I10: Thanh Tân | L10: ĐÃ HOÀN THÀNH
A11: 3 | B11: Xe bán tải | E11: 850000000 | G11: =E11 -> 850000000 | H11: Xe bán tải 2 cầu tự động | I11: Thanh Tân | L11: ĐÃ HOÀN THÀNH
A12: 4 | B12: Màn hình thông báo bay | E12: 360000000 | G12: =E12 -> 360000000 | H12: 06 Màn hình thông báo bay FIDS | I12: Thanh Tân | L12: Đang tiến hành hồ sơ mua sắm, hoàn thành trong tháng
A13: B | B13: SỬA CHỮA TÀI SẢN | C13: Column2 | D13: Column3 | E13: Column4 | F13: Column5 | G13: Column6 | H13: Column8
A14: 1 | B14: Sữa chữa đường công vụ A1: Gia cố nền chống bù vênh hằng năm đoạn trước băng chuyền Ovan, SC khu đọng nước trước bến 5-6 | C14: 62762103 | D14: 445000000 | E14: 105000000 | G14: 550000000 | H14: Sửa chữa khu đọng nước trước bến 5, bến 6: 220m2 Xử lý nền mòng đọan lún sụt do bên dưới có hàm ếch cạnh tunel: 150m x 1m Thảm BTN và sơn hoàn tín hiệu lại mặt đường sau khi SC nền mòng lún sụt: 160m x 5m | I14: Kiêm Thành, Tấn Phường
A15: 2 | B15: Sửa chữa các tấm đan | C15: 62762104 | E15: 100000000 | G15: 100000000 | H15: Sửa chữa các tấm đan | I15: Phương Tùng | L15: ĐÃ HOÀN THÀNH
A16: 3 | B16: Sửa chữa Trám vá các vết rỗ trên sân đỗ máy bay | C16: 62762106 | E16: 200000000 | G16: 200000000 | H16: Sửa chữa Trám vá các vết rỗ trên sân đỗ máy bay | I16: Phương Tùng | L16: HOÀN THÀNH TRONG NĂM
A17: 4 | B17: Sửa chữa mái tôn Nhà ga hàng hóa | C17: 62762188 | E17: 400000000 | H17: Sửa chữa mái tôn Nhà ga hàng hóa | I17: Phương Tùng | L17: HOÀN THÀNH TRONG NĂM
A18: 5 | B18: Sửa chữa máy phát điện 100KVA khu VP | C18: 62762209 | E18: 50000000 | G18: 50000000 | H18: Sửa chữa máy phát điện 100KVA khu VP | I18: Ngọc Ấn | L18: Đang làm thủ thục thanh toán
A19: 6 | B19: Sửa chữa xe cứu hỏa BAI VCA-121.05 | C19: 62762302 | E19: 600000000 | G19: 600000000 | H19: Sửa chữa thay thế Đồng hồ áp hệ thống bột, van khí nén, ống hơi, co hơi, xy lanh, đồng hồ tua bơm, lăng phun, bơm nước.. | I19: Sơn Hà | L19: ĐÃ HOÀN THÀNH
A20: 7 | B20: Thay thế cáp căng cửa tầng thang máy PL4 và cụm bánh xe ép tay vịn thang cuốn ES1, ES2, ES3, ES4 | C20: 62762203 | E20: 200000000 | G20: 200000000 | H20: Thang máy PL4: thay thế 01 sợi cáp căng cửa tầng Thang cuốn ES1, ES2, ES3, ES4: thay thế 32 cái cụm bánh xe ép tay vịn | I20: Sơn Hà | L20: ĐÃ HOÀN THÀNH
A21: 8 | B21: Sửa chữa bến bãi ô tô, sân đường | C21: 62762103 | E21: 950000000 | G21: 950000000 | H21: Sơn toàn bộ cầu cạn | I21: Phương Tùng | L21: ĐÃ HOÀN THÀNH
A22: C.2 | B22: SCTX MÁY MÓC THIẾT BỊ
A23: 2 | B23: Sửa chữa hệ thống ống lồng | C23: 62762202 | D23: 264000000 | E23: 150000000 | F23: 194248636 | G23: 219751364 | H23: 4 nhánh ống lồng QN, QT | I23: Khôi Nguyên, Công Đức | L23: Đang triển khai

Sheet TỔNG HỢP
A1: STT | B1: Danh mục Kế hoạch | C1: Mã Kế hoạch | D1: Bravo | E1: Được duyệt | F1: Đã thực hiện (Bravo) | G1: Đã thực hiện nhập liệu (Thực tế) | H1: Đã thực hiện thực tế | I1: Còn lại | K1: % thực hiện (Thực tế) | L1: Ghi chú | M1: Quy mô
A2: A | B2: SỬA CHỮA THƯỜNG XUYÊN | E2: =E3+E12+E31 -> 11169000000 | F2: =F3+F12+F31 -> 2523363419 | G2: =G3+G12+G31 -> 6.0629381e+09 | H2: =H3+H12+H31 -> 6.0715759e+09 | I2: =I3+I12+I31 -> 5.0974241e+09 | K2: =H2/E2 -> 0.54360963
A3: I | B3: SCTX CƠ SỞ HẠ TẦNG | E3: =SUM(E4:E11) -> 1149000000 | F3: =SUM(F4:F11) -> 303996215 | G3: =SUM(G4:G11) -> 3.5815168e+08 | H3: =SUM(H4:H11) -> 3.5815168e+08 | I3: =SUM(I4:I11) -> 7.9084832e+08 | K3: =H3/E3 -> 0.31170729
A4: 1 | B4: Sửa chữa nhà ga quốc nội | C4: 62762101 | D4: =VLOOKUP(C4,INFO!$B$2:$F$164,2,1) -> 2400000000 | E4: 260000000 | F4: =VLOOKUP(C4,INFO!$B$2:$F$164,5,1) -> 102604899 | G4: ='62762101'!F3 -> 140821619 | H4: =MAX(F4:G4) -> 140821619 | I4: =E4-H4 -> 119178381 | J4: =IFERROR(_xlfn.__XLUDF.DUMMYFUNCTION("SPARKLINE(J23, {""charttype"",""bar""; ""max"",MAX($J$23:$J$30); ""color1"",""green""})"),"#N/A") -> #N/A | K4: =H4/E4 -> 0.54162161 | M4: Sửa chửa kính, gạch vỡ, sơn tường cục bộ nhà ga và hư hỏng đột xuất khác | O4: ='62762101'!F3 -> 140821619 | P4: =B4 -> Sửa chữa nhà ga quốc nội
A5: 2 | B5: Sửa chữa bến bãi ô tô, sân đường | C5: 62762103 | D5: =VLOOKUP(C5,INFO!$B$2:$F$164,2,1) -> 3520000000 | E5: 110000000 | F5: 0 | G5: ='62762103'!F3 -> 62382513 | H5: =MAX(F5:G5) -> 62382513 | I5: =E5-H5 -> 47617487 | J5: =IFERROR(_xlfn.__XLUDF.DUMMYFUNCTION("SPARKLINE(J24, {""charttype"",""bar""; ""max"",MAX($J$23:$J$30); ""color1"",""green""})"),"#N/A") -> #N/A | K5: =H5/E5 -> 0.56711376 | M5: Sơn sửa, bảo trì các biển báo giao thông nội cảng, sửa chữa các gờ giảm tốc, các cọc tiêu mềm | O5: ='62762103'!F3 -> 62382513 | P5: =B5 -> Sửa chữa bến bãi ô tô, sân đường
A6: 3 | B6: Chi phí sửa chữa mương thoát nước | C6: 62762104 | D6: =VLOOKUP(C6,INFO!$B$2:$F$164,2,0) -> 69000000 | E6: 69000000 | F6: =VLOOKUP(C6,INFO!$B$2:$F$164,5,1) -> 3240741 | G6: ='62762104'!F3 -> 11090741 | H6: =MAX(F6:G6) -> 11090741 | I6: =E6-H6 -> 57909259 | J6: =IFERROR(_xlfn.__XLUDF.DUMMYFUNCTION("SPARKLINE(J25, {""charttype"",""bar""; ""max"",MAX($J$23:$J$30); ""color1"",""green""})"),"#N/A") -> #N/A | K6: =H6/E6 -> 0.16073537 | M6: Sửa chữa các tấm đan, mương bê tông xi măng nhà ga, sân dỗ ô tô, Out-House | O6: ='62762104'!F3 -> 11090741 | P6: =B6 -> Chi phí sửa chữa mương thoát nước
A7: 4 | B7: Chi phí cắt cỏ, nạo vét mương thoát nước | C7: 62762105 | D7: =VLOOKUP(C7,INFO!$B$2:$F$164,2,1) -> 30000000 | E7: 30000000 | F7: =VLOOKUP(C7,INFO!$B$2:$F$164,5,1) -> 0 | G7: ='62762105'!F3 -> 0 | H7: =MAX(F7:G7) -> 0 | I7: =E7-H7 -> 30000000 | J7: =IFERROR(_xlfn.__XLUDF.DUMMYFUNCTION("SPARKLINE(J26, {""charttype"",""bar""; ""max"",MAX($J$23:$J$30); ""color1"",""green""})"),"#N/A") -> #N/A | K7: =H7/E7 -> 0 | M7: Cắt cỏ, nạo vét các hố ga hố lọc rác | O7: ='62762105'!F3 -> 0 | P7: =B7 -> Chi phí cắt cỏ, nạo vét mương thoát nước
A8: 5 | B8: Sửa chữa sân đậu | C8: 62762106 | D8: =VLOOKUP(C8,INFO!$B$2:$F$164,2,0) -> 580000000 | E8: 420000000 | F8: =VLOOKUP(C8,INFO!$B$2:$F$164,5,1) -> 0 | G8: ='62762106'!F3 -> 0 | H8: =MAX(F8:G8) -> 0 | I8: =E8-H8 -> 420000000 | J8: =IFERROR(_xlfn.__XLUDF.DUMMYFUNCTION("SPARKLINE(J27, {""charttype"",""bar""; ""max"",MAX($J$23:$J$30); ""color1"",""green""})"),"#N/A") -> #N/A | K8: =H8/E8 -> 0 | M8: Sơn tín hiệu sân đậu | O8: ='62762106'!F3 -> 0 | P8: =B8 -> Sửa chữa sân đậu
A9: 6 | B9: Sửa chữa hàng rào | C9: 62762107 | D9: =VLOOKUP(C9,INFO!$B$2:$F$164,2,0) -> 60000000 | E9: 60000000 | F9: =VLOOKUP(C9,INFO!$B$2:$F$164,5,1) -> 0 | G9: ='62762107'!F3 -> 54788503 | H9: =MAX(F9:G9) -> 54788503 | I9: =E9-H9 -> 5211497.2 | J9: =IFERROR(_xlfn.__XLUDF.DUMMYFUNCTION("SPARKLINE(J28, {""charttype"",""bar""; ""max"",MAX($J$23:$J$30); ""color1"",""green""})"),"#N/A") -> #N/A | K9: =H9/E9 -> 0.91314171 | M9: Bảo dưỡng hàng rào khu Air side - Land side | O9: ='62762107'!F3 -> 54788503 | P9: =B9 -> Sửa chữa hàng rào
A10: 7 | B10: Sửa chữa nhà cửa, vật kiến trúc khác | C10: 62762188 | D10: =VLOOKUP(C10,INFO!$B$2:$F$164,2,0) -> 3230000000 | E10: 90000000 | F10: =VLOOKUP(C10,INFO!$B$2:$F$164,5,1) -> 198150575 | G10: ='62762188'!F3 -> 69293904 | H10: =G10 -> 69293904 | I10: =E10-H10 -> 20706096 | J10: =IFERROR(_xlfn.__XLUDF.DUMMYFUNCTION("SPARKLINE(J29, {""charttype"",""bar""; ""max"",MAX($J$23:$J$30); ""color1"",""green""})"),"#N/A") -> #N/A | K10: =H10/E10 -> 0.76993227 | M10: Sửa chữa Nhà xe nội bộ, kho cơ khí, kho cây xanh, Nhà xe ngoại trường, Nhà chứa rác, khu vực Trạm nguồn,… | O10: ='62762188'!F3 -> 69293904 | P10: =B10 -> Sửa chữa nhà cửa, vật kiến trúc khác
A11: 8 | B11: Sửa chữa nhà cửa, vật kiến trúc khác (khối gián tiếp) | C11: 62762189 | D11: =VLOOKUP(C11,INFO!$B$2:$F$164,2,0) -> 110000000 | E11: 110000000 | F11: =VLOOKUP(C11,INFO!$B$2:$F$164,5,1) -> 0 | G11: ='62762189'!F3 -> 19774400 | H11: =MAX(F11:G11) -> 19774400 | I11: =E11-H11 -> 90225600 | J11: =IFERROR(_xlfn.__XLUDF.DUMMYFUNCTION("SPARKLINE(J30, {""charttype"",""bar""; ""max"",MAX($J$23:$J$30); ""color1"",""green""})"),"#N/A") -> #N/A | K11: =H11/E11 -> 0.17976727 | M11: Sửa chữa thường xuyên, bảo dưỡng các nhà văn phòng, cầu thang…. | O11: ='62762189'!F3 -> 19774400 | P11: =B11 -> Sửa chữa nhà cửa, vật kiến trúc khác (khối gián tiếp)
A12: II | B12: SCTX MÁY MÓC THIẾT BỊ | E12: =SUM(E13:E30) -> 8240000000 | F12: =SUM(F13:F30) -> 1366281510 | G12: =SUM(G13:G30) -> 4.4846377e+09 | H12: =SUM(H13:H30) -> 4.4897761e+09 | I12: =SUM(I13:I30) -> 3.7502239e+09 | K12: =H12/E12 -> 0.54487574 | P12: =B12 -> SCTX MÁY MÓC THIẾT BỊ
A13: 9 | B13: Sửa chữa hệ thống băng chuyền | C13: 62762201 | D13: =VLOOKUP(C13,INFO!$B$2:$F$164,2,0) -> 920000000 | E13: 920000000 | F13: =VLOOKUP(C13,INFO!$B$2:$F$164,5,1) -> 13100000 | G13: ='62762201'!F3 -> 293060000 | H13: =MAX(F13:G13) -> 293060000 | I13: =E13-H13 -> 626940000 | J13: =IFERROR(_xlfn.__XLUDF.DUMMYFUNCTION("SPARKLINE(J32, {""charttype"",""bar""; ""max"",MAX($J$32:$J$49); ""color1"",""green""})"),"#N/A") -> #N/A | K13: =H13/E13 -> 0.31854348 | M13: Bảo dưỡng, sửa chữa băng chuyền | O13: ='62762201'!F3 -> 293060000 | P13: =B13 -> Sửa chữa hệ thống băng chuyền
A14: 10 | B14: Sửa chữa hệ thống ống lồng | C14: 62762202 | D14: =VLOOKUP(C14,INFO!$B$2:$F$164,2,0) -> 3480000000 | E14: 1180000000 | F14: =VLOOKUP(C14,INFO!$B$2:$F$164,5,1) -> 510932400 | G14: ='62762202'!F3 -> 335561400 | H14: =G14 -> 335561400 | I14: =E14-H14 -> 844438600 | J14: =IFERROR(_xlfn.__XLUDF.DUMMYFUNCTION("SPARKLINE(J33, {""charttype"",""bar""; ""max"",MAX($J$32:$J$49); ""color1"",""green""})"),"#N/A") -> #N/A | K14: =H14/E14 -> 0.28437407 | M14: Bảo dưỡng hệ thống ống lồng | O14: ='62762202'!F3 -> 335561400 | P14: =B14 -> Sửa chữa hệ thống ống lồng
A15: 11 | B15: Sửa chữa hệ thống thang cuốn, thang máy | C15: 62762203 | D15: =VLOOKUP(C15,INFO!$B$2:$F$164,2,0) -> 350000000 | E15: 350000000 | F15: =VLOOKUP(C15,INFO!$B$2:$F$164,5,1) -> 82210000 | G15: ='62762203'!F3 -> 200720000 | H15: =G15 -> 200720000 | I15: =E15-H15 -> 149280000 | J15: =IFERROR(_xlfn.__XLUDF.DUMMYFUNCTION("SPARKLINE(J34, {""charttype"",""bar""; ""max"",MAX($J$32:$J$49); ""color1"",""green""})"),"#N/A") -> #N/A | K15: =H15/E15 -> 0.57348571 | M15: Bảo dưỡng định kỳ thang máy thang cuốn và các hư hỏng nhỏ đột xuất khác | O15: ='62762203'!F3 -> 200720000 | P15: =B15 -> Sửa chữa hệ thống thang cuốn, thang máy
A16: 12 | B16: Sửa chữa hệ thống thông tin liên lạc | C16: 62762204 | D16: =VLOOKUP(C16,INFO!$B$2:$F$164,2,0) -> 180000000 | E16: 180000000 | F16: =VLOOKUP(C16,INFO!$B$2:$F$164,5,1) -> 7270000 | G16: ='62762204'!F3 -> 91169444 | H16: =MAX(F16:G16) -> 91169444 | I16: =E16-H16 -> 88830556 | J16: =IFERROR(_xlfn.__XLUDF.DUMMYFUNCTION("SPARKLINE(J35, {""charttype"",""bar""; ""max"",MAX($J$32:$J$49); ""color1"",""green""})"),"#N/A") -> #N/A | K16: =H16/E16 -> 0.50649691 | M16: Bảo trì, bảo dưỡng hệ thống thông tin liên lạc | O16: ='62762204'!F3 -> 91169444 | P16: =B16 -> Sửa chữa hệ thống thông tin liên lạc
A17: 13 | B17: Sửa chữa hệ thống quầy thủ tục, thiết bị nội thất | C17: 62762205 | D17: =VLOOKUP(C17,INFO!$B$2:$F$164,2,0) -> 10000000 | E17: 10000000 | F17: =VLOOKUP(C17,INFO!$B$2:$F$164,5,1) -> 0 | G17: ='62762205'!F3 -> 0 | H17: =MAX(F17:G17) -> 0 | I17: =E17-H17 -> 10000000 | J17: =IFERROR(_xlfn.__XLUDF.DUMMYFUNCTION("SPARKLINE(J36, {""charttype"",""bar""; ""max"",MAX($J$32:$J$49); ""color1"",""green""})"),"#N/A") -> #N/A | K17: =H17/E17 -> 0 | M17: Bảo trì, sửa chữa 24 quầy thủ tục | O17: ='62762205'!F3 -> 0 | P17: =B17 -> Sửa chữa hệ thống quầy thủ tục, thiết bị nội thất
A18: 14 | B18: Sửa chữa hệ thống máy móc, thiết bị làm thủ tục | C18: 62762206 | D18: =VLOOKUP(C18,INFO!$B$2:$F$164,2,0) -> 90000000 | E18: 90000000 | F18: =VLOOKUP(C18,INFO!$B$2:$F$164,5,1) -> 0 | G18: ='62762206'!F3 -> 9318519 | H18: =MAX(F18:G18) -> 9318519 | I18: =E18-H18 -> 80681481 | J18: =IFERROR(_xlfn.__XLUDF.DUMMYFUNCTION("SPARKLINE(J37, {""charttype"",""bar""; ""max"",MAX($J$32:$J$49); ""color1"",""green""})"),"#N/A") -> #N/A | K18: =H18/E18 -> 0.1035391 | M18: Sửa chữa thay thế màn hình, các thiết bị quầy thủ tục | O18: ='62762206'!F3 -> 9318519 | P18: =B18 -> Sửa chữa hệ thống máy móc, thiết bị làm thủ tục
A19: 15 | B19: Sửa chữa hệ thống thiết bị vệ sinh | C19: 62762207 | D19: =VLOOKUP(C19,INFO!$B$2:$F$164,2,0) -> 760000000 | E19: 80000000 | F19: =VLOOKUP(C19,INFO!$B$2:$F$164,5,1) -> 0 | G19: ='62762207'!F3 -> 5850000 | H19: =MAX(F19:G19) -> 5850000 | I19: =E19-H19 -> 74150000 | J19: =IFERROR(_xlfn.__XLUDF.DUMMYFUNCTION("SPARKLINE(J38, {""charttype"",""bar""; ""max"",MAX($J$32:$J$49); ""color1"",""green""})"),"#N/A") -> #N/A | K19: =H19/E19 -> 0.073125 | M19: Bảo dưỡng sửa chữa thiết bị vệ sinh | O19: ='62762207'!F3 -> 5850000 | P19: =B19 -> Sửa chữa hệ thống thiết bị vệ sinh
A20: 16 | B20: Sửa chữa máy móc thiết bị kiểm tra an ninh | C20: 62762208 | D20: =VLOOKUP(C20,INFO!$B$2:$F$164,2,0) -> 170000000 | E20: 170000000 | F20: =VLOOKUP(C20,INFO!$B$2:$F$164,5,1) -> 0 | G20: ='62762208'!F3 -> 0 | H20: =MAX(F20:G20) -> 0 | I20: =E20-H20 -> 170000000 | J20: =IFERROR(_xlfn.__XLUDF.DUMMYFUNCTION("SPARKLINE(J39, {""charttype"",""bar""; ""max"",MAX($J$32:$J$49); ""color1"",""green""})"),"#N/A") -> #N/A | K20: =H20/E20 -> 0 | M20: Bảo trì bảo dưỡng máy soi cổng từ, máy dò chất nổ | O20: ='62762208'!F3 -> 0 | P20: =B20 -> Sửa chữa máy móc thiết bị kiểm tra an ninh
A21: 17 | B21: Sửa chữa máy móc, thiết bị , hệ thống thiết bị điện | C21: 62762209 | D21: =VLOOKUP(C21,INFO!$B$2:$F$164,2,0) -> 2050000000 | E21: 730000000 | F21: =VLOOKUP(C21,INFO!$B$2:$F$164,5,1) -> 165545096 | G21: ='62762209'!F3 -> 2.1596921e+08 | H21: =MAX(F21:G21) -> 2.1596921e+08 | I21: =E21-H21 -> 5.1403079e+08 | J21: =IFERROR(_xlfn.__XLUDF.DUMMYFUNCTION("SPARKLINE(J40, {""charttype"",""bar""; ""max"",MAX($J$32:$J$49); ""color1"",""green""})"),"#N/A") -> #N/A | K21: =H21/E21 -> 0.29584823 | M21: Bảo trì bảo dưỡng hệ thống thiết bị điện, máy phát điện, hệ thống chống sét, hệ thống UPS, hệ thống quạt thông gió | O21: ='62762209'!F3 -> 2.1596921e+08 | P21: =B21 -> Sửa chữa máy móc, thiết bị , hệ thống thiết bị điện
A22: 18 | B22: Sửa chữa máy móc, thiết bị , hệ thống thiết bị lạnh | C22: 62762210 | D22: =VLOOKUP(C22,INFO!$B$2:$F$164,2,0) -> 2970000000 | E22: 2970000000 | F22: =VLOOKUP(C22,INFO!$B$2:$F$164,5,1) -> 78720000 | G22: ='62762210'!F3 -> 2.7839956e+09 | H22: =G22 -> 2.7839956e+09 | I22: =E22-H22 -> 1.8600441e+08 | J22: =IFERROR(_xlfn.__XLUDF.DUMMYFUNCTION("SPARKLINE(J41, {""charttype"",""bar""; ""max"",MAX($J$32:$J$49); ""color1"",""green""})"),"#N/A") -> #N/A | K22: =H22/E22 -> 0.93737225 | M22: Bảo dưỡng hệ thống Chiller định kỳ, tháp giải nhiệt, hệ thống máy lạnh cục bộ, hệ thống lạnh | O22: ='62762210'!F3 -> 2.7839956e+09 | P22: =B22 -> Sửa chữa máy móc, thiết bị , hệ thống thiết bị lạnh
A23: 19 | B23: Sửa chữa thiết bị PCCC | C23: 62762211 | D23: =VLOOKUP(C23,INFO!$B$2:$F$164,2,0) -> 290000000 | E23: 290000000 | F23: =VLOOKUP(C23,INFO!$B$2:$F$164,5,1) -> 33958680 | G23: ='62762211'!F3 -> 74200926 | H23: =MAX(F23:G23) -> 74200926 | I23: =E23-H23 -> 2.1579907e+08 | J23: =IFERROR(_xlfn.__XLUDF.DUMMYFUNCTION("SPARKLINE(J42, {""charttype"",""bar""; ""max"",MAX($J$32:$J$49); ""color1"",""green""})"),"#N/A") -> #N/A | K23: =H23/E23 -> 0.25586526 | M23: Bảo dưỡng sửa chữa hệ thống báo cháy | O23: ='62762211'!F3 -> 74200926 | P23: =B23 -> Sửa chữa thiết bị PCCC
A24: 20 | B24: Sửa chữa hệ thống xử lý chất thải | C24: 62762212 | D24: =VLOOKUP(C24,INFO!$B$2:$F$164,2,0) -> 880000000 | E24: 390000000 | F24: =VLOOKUP(C24,INFO!$B$2:$F$164,5,1) -> 94283500 | G24: ='62762212'!F3 -> 94283500 | H24: =MAX(F24:G24) -> 94283500 | I24: =E24-H24 -> 295716500 | J24: =IFERROR(_xlfn.__XLUDF.DUMMYFUNCTION("SPARKLINE(J43, {""charttype"",""bar""; ""max"",MAX($J$32:$J$49); ""color1"",""green""})"),"#N/A") -> #N/A | K24: =H24/E24 -> 0.24175256 | M24: Bảo dưỡng sửa chữa hệ thống xử lý chất thải | O24: ='62762212'!F3 -> 94283500 | P24: =B24 -> Sửa chữa hệ thống xử lý chất thải
A25: 21 | B25: Sửa chữa hệ thống cấp nước | C25: 62762213 | D25: =VLOOKUP(C25,INFO!$B$2:$F$164,2,0) -> 780000000 | E25: 80000000 | F25: =VLOOKUP(C25,INFO!$B$2:$F$164,5,1) -> 13491000 | G25: ='62762213'!F3 -> 13491000 | H25: =MAX(F25:G25) -> 13491000 | I25: =E25-H25 -> 66509000 | J25: =IFERROR(_xlfn.__XLUDF.DUMMYFUNCTION("SPARKLINE(J44, {""charttype"",""bar""; ""max"",MAX($J$32:$J$49); ""color1"",""green""})"),"#N/A") -> #N/A | K25: =H25/E25 -> 0.1686375 | M25: Bảo dưỡng sửa chữa hệ thống cấp nước | O25: ='62762213'!F3 -> 13491000 | P25: =B25 -> Sửa chữa hệ thống cấp nước
A26: 22 | B26: Sửa chữa hệ thống thoát nước | C26: 62762214 | D26: =VLOOKUP(C26,INFO!$B$2:$F$164,2,0) -> 40000000 | E26: 40000000 | F26: =VLOOKUP(C26,INFO!$B$2:$F$164,5,1) -> 0 | G26: ='62762214'!F3 -> 0 | H26: =MAX(F26:G26) -> 0 | I26: =E26-H26 -> 40000000 | J26: =IFERROR(_xlfn.__XLUDF.DUMMYFUNCTION("SPARKLINE(J45, {""charttype"",""bar""; ""max"",MAX($J$32:$J$49); ""color1"",""green""})"),"#N/A") -> #N/A | K26: =H26/E26 -> 0 | M26: Bảo dưỡng sửa chữa hệ thống thoát nước | O26: ='62762214'!F3 -> 0 | P26: =B26 -> Sửa chữa hệ thống thoát nước
A27: 23 | B27: Sửa chữa hệ thống trạm thu phí | C27: 62762215 | D27: =VLOOKUP(C27,INFO!$B$2:$F$164,2,0) -> 570000000 | E27: 370000000 | F27: =VLOOKUP(C27,INFO!$B$2:$F$164,5,1) -> 351588400 | G27: ='62762215'!F3 -> 346450000 | H27: =MAX(F27:G27) -> 351588400 | I27: =E27-H27 -> 18411600 | J27: =IFERROR(_xlfn.__XLUDF.DUMMYFUNCTION("SPARKLINE(J46, {""charttype"",""bar""; ""max"",MAX($J$32:$J$49); ""color1"",""green""})"),"#N/A") -> #N/A | K27: =H27/E27 -> 0.95023892 | M27: Bảo dưỡng sửa chữa hệ thống trạm thu phí | O27: ='62762215'!F3 -> 346450000 | P27: =B27 -> Sửa chữa hệ thống trạm thu phí
A28: 24 | B28: Sửa chữa hệ thống thiết bị phục vụ máy bay | C28: 62762216 | D28: =VLOOKUP(C28,INFO!$B$2:$F$164,2,0) -> #N/A | O28: ='62762216'!F3 -> 0 | P28: =B28 -> Sửa chữa hệ thống thiết bị phục vụ máy bay
A29: 25 | B29: Sửa chữa hệ thống camera, CCTV | C29: 62762217 | D29: =VLOOKUP(C29,INFO!$B$2:$F$164,2,0) -> 300000000 | E29: 300000000 | F29: =VLOOKUP(C29,INFO!$B$2:$F$164,5,1) -> 0 | G29: ='62762217'!F3 -> 0 | H29: =MAX(F29:G29) -> 0 | I29: =E29-H29 -> 300000000 | J29: =IFERROR(_xlfn.__XLUDF.DUMMYFUNCTION("SPARKLINE(J48, {""charttype"",""bar""; ""max"",MAX($J$32:$J$49); ""color1"",""green""})"),"#N/A") -> #N/A | K29: =H29/E29 -> 0 | M29: Bảo dưỡng sửa chữa hệ thống camera, CCTV | O29: ='62762217'!F3 -> 0 | P29: =B29 -> Sửa chữa hệ thống camera, CCTV
A30: 26 | B30: Sửa chữa máy móc thiết bị khác | C30: 62762288 | D30: =VLOOKUP(C30,INFO!$B$2:$F$164,2,0) -> 90000000 | E30: 90000000 | F30: =VLOOKUP(C30,INFO!$B$2:$F$164,5,1) -> 15182434 | G30: ='62762288'!F3 -> 20568148 | H30: =MAX(F30:G30) -> 20568148 | I30: =E30-H30 -> 69431852 | J30: =IFERROR(_xlfn.__XLUDF.DUMMYFUNCTION("SPARKLINE(J49, {""charttype"",""bar""; ""max"",MAX($J$32:$J$49); ""color1"",""green""})"),"#N/A") -> #N/A | K30: =H30/E30 -> 0.22853498 | M30: Bảo dưỡng sửa chữa máy nước uống, chà sàn, máy cắt cỏ, máy đóng gói hành lý và các thiết bị khác | O30: ='62762288'!F3 -> 20568148 | P30: =B30 -> Sửa chữa máy móc thiết bị khác
A31: III | B31: SCTX PHƯƠNG TIỆN VẬN TẢI | E31: =SUM(E32:E35) -> 1780000000 | F31: =SUM(F32:F35) -> 853085694 | G31: =SUM(G32:G35) -> 1.2201487e+09 | H31: =SUM(H32:H35) -> 1.2236481e+09 | I31: =SUM(I32:I35) -> 5.5635189e+08 | K31: =H31/E31 -> 0.68744276 | P31: =B31 -> SCTX PHƯƠNG TIỆN VẬN TẢI
A32: 27 | B32: Sửa chữa phương tiện vận tải đặc chủng phục vụ bay | C32: 62762301 | D32: =VLOOKUP(C32,INFO!$B$2:$F$164,2,0) -> 2720000000 | E32: 1260000000 | F32: =VLOOKUP(C32,INFO!$B$2:$F$164,5,1) -> 581779517 | G32: ='62762301'!F3 -> 7.8329641e+08 | H32: =MAX(F32:G32) -> 7.8329641e+08 | I32: =E32-H32 -> 4.7670359e+08 | K32: =H32/E32 -> 0.62166381 | M32: Bảo dưỡng sửa chữa chuyển mùa phương tiện vận tải đặc chủng phục vụ bay | O32: ='62762301'!F3 -> 7.8329641e+08 | P32: =B32 -> Sửa chữa phương tiện vận tải đặc chủng phục vụ bay
A33: 28 | B33: Sửa chữa xe cứu hỏa, cứu thương, xe chuyên dùng | C33: 62762302 | D33: =VLOOKUP(C33,INFO!$B$2:$F$164,2,0) -> 600000000 | E33: 390000000 | F33: =VLOOKUP(C33,INFO!$B$2:$F$164,5,1) -> 230464464 | G33: ='62762302'!F3 -> 3.9530822e+08 | H33: =G33 -> 3.9530822e+08 | I33: =E33-H33 -> -5308217.8 | K33: =H33/E33 -> 1.0136108 | M33: Bảo dưỡng sửa chữa các xe cứu hoả, cứu thương, xe chuyên dùng | O33: ='62762302'!F3 -> 3.9530822e+08 | P33: =B33 -> Sửa chữa xe cứu hỏa, cứu thương, xe chuyên dùng
A34: 29 | B34: Sửa chữa xe ô tô, xe tải các loại | C34: 62762303 | D34: =VLOOKUP(C34,INFO!$B$2:$F$164,2,0) -> 100000000 | E34: 100000000 | F34: =VLOOKUP(C34,INFO!$B$2:$F$164,5,1) -> 32430749 | G34: ='62762303'!F3 -> 28931349 | H34: =MAX(F34:G34) -> 32430749 | I34: =E34-H34 -> 67569251 | K34: =H34/E34 -> 0.32430749 | M34: Bảo dưỡng sửa chữa các xe 15 chỗ và xe tải các loại | O34: ='62762303'!F3 -> 28931349 | P34: =B34 -> Sửa chữa xe ô tô, xe tải các loại
A35: 30 | B35: Sửa chữa xe ô tô (khối gián tiếp) | C35: 62762304 | D35: =VLOOKUP(C35,INFO!$B$2:$F$164,2,0) -> 30000000 | E35: 30000000 | F35: =VLOOKUP(C35,INFO!$B$2:$F$164,5,1) -> 8410964 | G35: ='62762304'!F3 -> 12612737 | H35: =MAX(F35:G35) -> 12612737 | I35: =E35-H35 -> 17387263 | K35: =H35/E35 -> 0.42042457 | M35: Bảo dưỡng sửa chữa các xe ô tô 4 chỗ, 7 chỗ… | O35: ='62762304'!F3 -> 12612737 | P35: =B35 -> Sửa chữa xe ô tô (khối gián tiếp)
A36: 31 | B36: Sửa chữa phương tiện vận tải khác | C36: 62762388 | F36: =IFERROR(VLOOKUP(C36,INFO!$B$2:$F$164,5,0),"") | G36: =IF('62762388'!E3<E36,E36,'62762388'!E3) -> 0 | O36: ='62762388'!F3 -> 0 | P36: =B36 -> Sửa chữa phương tiện vận tải khác
B37: CÁC CHI PHÍ KHÁC | P37: =B37 -> CÁC CHI PHÍ KHÁC
A38: 41 | B38: Thuê dịch vụ vệ sinh | C38: 627701 | D38: =VLOOKUP(C38,INFO!$B$2:$F$164,2,0) -> 930000000 | E38: 930000000 | F38: =VLOOKUP(C38,INFO!$B$2:$F$164,5,1) -> 158714210 | G38: ='627701'!F3 -> 660895710 | H38: =MAX(F38:G38) -> 660895710 | I38: =E38-H38 -> 269104290 | K38: =H38/E38 -> 0.71064055 | N38: -280000000 | O38: ='627701'!F3 -> 660895710 | P38: =B38 -> Thuê dịch vụ vệ sinh
A39: 42 | B39: Thuê dịch vụ bảo vệ | C39: 627702 | D39: =VLOOKUP(C39,INFO!$B$2:$F$164,2,0) -> 360000000 | E39: 360000000 | F39: =VLOOKUP(C39,INFO!$B$2:$F$164,5,1) -> 137293626 | G39: ='627702'!F3 -> 306662400 | H39: =MAX(F39:G39) -> 306662400 | I39: =E39-H39 -> 53337600 | K39: =H39/E39 -> 0.85184 | N39: -40000000 | O39: ='627702'!F3 -> 306662400 | P39: =B39 -> Thuê dịch vụ bảo vệ
A40: 43 | B40: Thuê dịch vụ vệ sinh môi trường, chất thải | C40: 627703 | D40: =VLOOKUP(C40,INFO!$B$2:$F$164,2,0) -> 120000000 | E40: 120000000 | F40: =VLOOKUP(C40,INFO!$B$2:$F$164,5,1) -> 28096366 | G40: ='627703'!F3 -> 0 | H40: =MAX(F40:G40) -> 28096366 | I40: =E40-H40 -> 91903634 | K40: =H40/E40 -> 0.23413638 | N40: 0 | O40: ='627703'!F3 -> 0 | P40: =B40 -> Thuê dịch vụ vệ sinh môi trường, chất thải
...

Sheet 62721
A2: STT | B2: Danh mục | C2: Mã khoản mục chi phí | D2: ĐƯỢC DUYỆT | E2: BỔ SUNG | F2: THỰC HIỆN | G2: CÒN LẠI/ TIẾN ĐỘ | H2: QUY MÔ | I2: NGƯỜI THỰC HIỆN | J2: MỤC LỤC
B3: Chi phí nhiên liệu | C3: 62721 | D3: =VLOOKUP(C3,'TỔNG HỢP'!$C$4:$P$84,3,0) -> 800000000 | F3: =SUM(F4:F889) -> 0 | G3: =D3-F3 -> 800000000
A21: 1
A22: 2

Sheet 62722
A2: STT | B2: Danh mục | C2: Mã khoản mục chi phí | D2: ĐƯỢC DUYỆT | E2: BỔ SUNG | F2: THỰC HIỆN | G2: CÒN LẠI | H2: QUY MÔ | I2: NGƯỜI THỰC HIỆN | J2: MỤC LỤC
B3: Vật tư vệ sinh | C3: 62722 | D3: =VLOOKUP(C3,'TỔNG HỢP'!$C$4:$P$84,3,0) -> 150000000 | F3: =SUM(F4:F889) -> 1.4981388e+08 | G3: =D3-F3 -> 186116.85
B4: Mua giấy vệ sinh và bao rác | F4: 59035735 | H4: 46071 | I4: Nhung
B5: Mua giấy vệ sinh và bao rác | F5: =49150000/1.08 -> 45509259 | H5: 46162 | I5: Nhung
B6: Mua giấy vệ sinh và bao rác | F6: =48890400/1.08 -> 45268889 | H6: 46307 | I6: Nhung
B16: Mua giấy vệ sinh | E16: 24520000 | H16: 45677 | I16: Nhung
B17: Bao rác đen đại 80x100cm | E17: =80*38194 -> 3055520 | H17: 45701
B18: Mua giấy vệ sinh và bao rác (hợp đồng nguyên tắc 21.600.000đ/tháng) | E18: 216000000 | H18: 45733 | I18: Nhung
B19: Siniguard, paraffin, Hóa chất tảy, pad chà sàn | E19: 9807723 | H19: 45733 | I19: Nhung
B20: Eco Anti-Bac | E20: 1475000 | H20: 45923 | I20: Nhung
A21: 1 | B21: Tẩy căn canxi | E21: 687000 | H21: 45926 | I21: Nhung
A22: 2 | B22: Cây lau nhà mút xốp xàm | E22: 1600000 | H22: 45985 | I22: Nhung

Sheet 62723
A2: STT | B2: Danh mục | C2: Mã khoản mục chi phí | D2: ĐƯỢC DUYỆT | E2: BỔ SUNG | F2: SỐ TIỀN ĐÃ/ ĐANG THỰC HIỆN | G2: CÒN LẠI/ TIẾN ĐỘ | H2: QUY MÔ | I2: NGƯỜI THỰC HIỆN | J2: MỤC LỤC
B3: =VLOOKUP(C3,'TỔNG HỢP'!$C$4:$P$84,14,0) -> Vật tư, tem, nhãn kiểm tra an ninh hàng không | C3: 62723 | D3: =VLOOKUP(C3,'TỔNG HỢP'!$C$4:$P$84,3,0) -> 20000000 | F3: =SUM(F4:F889) -> 0
A21: 1
A22: 2

Sheet 62724
A2: STT | B2: Danh mục | C2: Mã khoản mục chi phí | D2: ĐƯỢC DUYỆT | E2: BỔ SUNG | F2: SỐ TIỀN ĐÃ/ ĐANG THỰC HIỆN | G2: CÒN LẠI/ TIẾN ĐỘ | H2: QUY MÔ | I2: NGƯỜI THỰC HIỆN | J2: MỤC LỤC
B3: Vật liệu phục vụ chuyến bay | C3: 62724 | D3: =VLOOKUP(C3,'TỔNG HỢP'!$C$4:$P$84,3,0) -> 28000000 | F3: =SUM(F4:F900) -> 19394320 | G3: =D3-F3 -> 8605680
B4: Biểu mẫu phục vụ chuyến bay | F4: 5420000 | H4: 46112 | I4: Khanh
B5: Lưới phủ mâm hàng | F5: 4000000 | H5: 46112 | I5: Khanh
B6: Photo biểu mẫu phục vụ chuyến bay | F6: 908000 | H6: 46146 | I6: Tân Hoa
B7: Photo biểu mẫu phục vụ chuyến bay | F7: 442800 | H7: 46153 | I7: Bách
B8: Photo biểu mẫu phục vụ chuyến bay | F8: 1260000 | H8: 46191 | I8: Tân Hoa
B9: Photo biểu mẫu phục vụ chuyến bay | F9: =535680/1.08 -> 496000 | H9: 46202 | I9: Bách
B10: Photo biểu mẫu phục vụ chuyến bay | F10: 1260000 | H10: 46217 | I10: Tân Hoa
B11: Photo biểu mẫu phục vụ chuyến bay | F11: 626400 | H11: 46237 | I11: Bách
B12: Photo biểu mẫu phục vụ chuyến bay | F12: 1260000 | H12: 46245 | I12: Tân Hoa
B13: Photo biểu mẫu phục vụ chuyến bay | F13: 484000 | H13: 46272 | I13: Bách
B14: Photo biểu mẫu phục vụ chuyến bay | F14: 1260000 | H14: 46274 | I14: Tân Hoa
B15: Photo biểu mẫu phục vụ chuyến bay | F15: 1260000 | H15: 46304 | I15: Tân Hoa
B16: Photo biểu mẫu phục vụ chuyến bay | F16: 717120 | H16: 46308 | I16: Bách
B29: Photo biểu mẫu phục vụ chuyến bay | D29: đưa về mã PVB | E29: 4944000 | H29: 45712 | I29: Tân Hoa
B30: In Bingo card, phiếu kiểm soát chuyến bay | D30: đưa về mã PVB | E30: 9300000 | H30: 45749 | I30: Trân
B31: Photo biểu mẫu phục vụ chuyến bay | D31: đưa về mã PVB | E31: 3500000 | H31: 45800 | I31: Tân Hoa
B32: Biểu mẫu phục vụ chuyến bay | D32: đưa về mã PVB | E32: 3200000 | H32: 45915 | I32: Tân Hoa

Sheet 62725
A2: STT | B2: Danh mục | C2: Mã khoản mục chi phí | D2: ĐƯỢC DUYỆT | E2: BỔ SUNG | F2: THỰC HIỆN | G2: CÒN LẠI/ TIẾN ĐỘ | H2: Ngày | I2: NGƯỜI THỰC HIỆN | J2: MỤC LỤC
B3: Vật liệu xử lý chất thải, hóa chất hệ thống lạnh | C3: 62725 | D3: =VLOOKUP(C3,'TỔNG HỢP'!$C$4:$P$84,3,0) -> 126000000 | F3: =SUM(F4:F889) -> 87955140 | G3: =D3-F3 -> 38044860
B4: Hóa chất xử lý nước chống cáu cặn số lượng dùng trong 06 tháng | F4: 87955140 | H4: 46150 | I4: Tân
B18: Hóa chất xử lý nước chống cáu cặn số lượng dùng trong 06 tháng | E18: 87955140 | H18: 45698 | I18: Tân
B19: Hóa chất xử lý nước chống cáu cặn số lượng dùng trong 06 tháng | E19: 87955140 | G19: 87955140 | H19: 45839 | I19: Tân
A21: 1
A22: 2 | B22: Hóa chất xử lý nước cho hệ thống điều hòa | H22: 45454 | I22: Tân
B23: Hóa chất và dịch vụ tẩy cáu cặn đường ống làm mát bình ngưng của 02 Chiller | H23: 45579 | I23: Cống Đức

Sheet 62726
A2: STT | B2: Danh mục | C2: Mã khoản mục chi phí | D2: ĐƯỢC DUYỆT | E2: BỔ SUNG | F2: SỐ TIỀN ĐÃ/ ĐANG THỰC HIỆN | G2: CÒN LẠI/ TIẾN ĐỘ | H2: QUY MÔ | I2: NGƯỜI THỰC HIỆN | J2: MỤC LỤC
B3: =VLOOKUP(C3,'TỔNG HỢP'!$C$4:$P$84,14,0) -> Vật tư in ấn vé sân đường, hóa đơn | C3: 62726 | D3: =VLOOKUP(C3,'TỔNG HỢP'!$C$4:$P$84,3,0) -> 20000000 | F3: =SUM(F4:F889) -> 2000000
B4: Giấy in nhiệt | F4: 2000000 | H4: 46112 | I4: Lan
A21: 1
A22: 2

Sheet 62727
A2: STT | B2: Danh mục | C2: Mã khoản mục chi phí | D2: ĐƯỢC DUYỆT | E2: BỔ SUNG | F2: SỐ TIỀN ĐÃ/ ĐANG THỰC HIỆN | G2: CÒN LẠI/ TIẾN ĐỘ | H2: QUY MÔ | I2: NGƯỜI THỰC HIỆN | J2: MỤC LỤC
B3: =VLOOKUP(C3,'TỔNG HỢP'!$C$4:$P$84,14,0) -> Chi phí nhiên liệu phục vụ công tác | C3: 62727 | D3: =VLOOKUP(C3,'TỔNG HỢP'!$C$4:$P$84,3,0) -> 75000000 | F3: =SUM(F4:F889) -> 0
A21: 1
A22: 2

Sheet 627311
A2: STT | B2: Danh mục | C2: Mã khoản mục chi phí | D2: ĐƯỢC DUYỆT | E2: ĐỀ XUẤT CUỐI NĂM | F2: SỐ TIỀN THỰC HIỆN | G2: CÒN LẠI | H2: CÒN LẠI/ TIẾN ĐỘ | I2: Ngày | J2: Người thực hiện | K2: MỤC LỤC
B3: Công cụ dụng cụ lao động | C3: 627311 | D3: =VLOOKUP(C3,'TỔNG HỢP'!$C$4:$P$84,3,0) -> 650000000 | E3: =SUM(E4:E62) -> 1.8589667e+08 | F3: =SUM(F4:F76) -> 3.5349265e+08 | G3: =D3-E3-F3 -> 1.1061068e+08 | H3: =D3-F3 -> 2.9650735e+08
B4: Máy nén cao áp (Nhà xe ngoại trường) | F4: =7039500/1.08 -> 6518055.6 | I4: 46031 | J4: Chính Trung
B5: Tủ hồ sơ 6 tủ PVMĐ | F5: 20400000 | I5: 46048 | J5: Thúy
B6: Máy scan Brother | F6: 8500000 | I6: 46050 | J6: Trân | M6: STT | N6: Tên hạng mục kế hoạch | O6: Đvt | P6: Số lượng hiện có | Q6: Đơn giá | R6: KẾ HOẠCH 2026 | T6: Ghi chú
B7: Ghế ngồi quầy thủ tục 12 cái | F7: 12000000 | I7: 46057 | J7: Tân | R7: Số lượng | S7: Thành tiền
B8: Gia công thùng FOD khu vực sân đỗ tàu bay | F8: 3040000 | I8: 46100 | J8: Nguyên | M8: I | N8: CÔNG CỤ DỤNG CỤ LAO ĐỘNG: | S8: =SUM(S9:S43) -> 855500000
B9: 2 Tủ nhựa Duy Tân (A Hoa) | F9: =1320000/1.08 -> 1222222.2 | I9: 46112 | J9: Khanh | N9: TRANG BỊ PHỤC VỤ ĐÁNH GIÁ NÂNG CẤP CẢNG HÀNG KHÔNG 4 SAO
B10: Máy scan cho Đội VS và VH TBB | F10: =17300000/1.08 -> 16018519 | I10: 46112 | J10: Khanh | N10: Bảng led khu vực chờ xe | O10: cái | Q10: 20000000 | R10: 1 | S10: =Q10*R10 -> 20000000 | T10: 4 sao
B11: Chóp an toàn (20 cái) | F11: 8640000 | I11: 46112 | J11: Khanh | N11: Xe đẩy trẻ em chuẩn sân bay | O11: cái | Q11: 20000000 | R11: 20 | S11: =Q11*R11 -> 400000000 | T11: 4 sao
B12: Ghế gấp gọn phòng cha mẹ (2 cái) | D12: TC 4 Sao | F12: =550000*2 -> 1100000 | G12: đã thực hiện | H12: đã thực hiện | I12: 46129 | J12: Nhung | N12: Loa phục vụ hành khách đặc biệt | O12: cái | Q12: 5000000 | R12: 2 | S12: =Q12*R12 -> 10000000 | T12: 4 sao
B13: Thang bồn cầu trẻ em (8 cái) | F13: =8*599000 -> 4792000 | I13: 46129 | J13: Nhung | N13: Trụ sạc điện thoại | O13: cái | Q13: 10000000 | R13: 5 | S13: =Q13*R13 -> 50000000 | T13: 4 sao
B14: Máy đầm cóc (Khu bay) | F14: =19820000/1.08 -> 18351852 | I14: 46178 | J14: Ngân | N14: Thùng rác WC có nắp theo tiêu chuẩn | O14: cái | Q14: 1000000 | R14: 100 | S14: =Q14*R14 -> 100000000 | T14: 4 sao
B15: Áo phao | F15: 10150000 | I15: 46189 | J15: Tân | N15: PHÒNG KỸ THUẬT HẠ TẦNG
B16: Máy đo nồng độ cồn | F16: 13775000 | I16: 46191 | J16: Thiện | N16: Máy cắt cỏ 02 thì | O16: cái | Q16: 4000000 | R16: 2 | S16: =Q16*R16 -> 8000000
B17: Bàn thay tã gắn tường (01 cái) | D17: TC 4 Sao | F17: 4500000 | G17: =SUM(F17:F24) -> 90530336 | H17: =SUM(F17:F24) -> 90530336 | I17: 46237 | J17: Nhung | N17: Bộ đàm | O17: cái | Q17: 7500000 | R17: 3 | S17: =Q17*R17 -> 22500000
B18: Máy đa năng hâm sữa cho bé (5c phòng cha mẹ) | D18: TC 4 Sao | F18: 5697743 | I18: 46237 | J18: Nhung | N18: PHÒNG PHỤC VỤ MẶT ĐẤT
B19: Máy khuếch tán tinh dầu (14 cái) | D19: TC 4 Sao | F19: =57258400/1.08 -> 53017037 | I19: 46237 | J19: Nhung | K19: Hiện đang mua trước 1 cái | N19: Bộ đàm | O19: cái | P19: 16 | Q19: 7500000 | R19: 6 | S19: =Q19*R19 -> 45000000
B20: Ghế gấp gọn phòng cha mẹ (4 cái) | D20: TC 4 Sao | F20: 2200000 | I20: 46237 | J20: Nhung | N20: Máy scan EPSON DS-530II | O20: cái | Q20: 9000000 | R20: 1 | S20: =Q20*R20 -> 9000000 | T20: Phòng PVHK
B21: Thùng rác có nắp WC (90 cái) | D21: TC 4 Sao | F21: =18792000/1.08 -> 17400000 | I21: 46237 | J21: Nhung | K21: 5 cái 10L, 85 cái 15L (thùng rác nhựa) | N21: Điện thoại PANA để bàn | O21: cái | P21: 8 | Q21: 2000000 | R21: 4 | S21: =Q21*R21 -> 8000000 | T21: Phòng PVHK
B22: Thùng rác có nắp WC (đang mua mẫu 2 cái Nhựa) | D22: TC 4 Sao | F22: =350400/1.08 -> 324444.44 | I22: 46237 | J22: Nhung
B23: Thùng rác có nắp WC (đang mua mẫu 1 cái INOX) | D23: TC 4 Sao | F23: 780000 | I23: 46259 | J23: Nhung
B24: Xe đẩy trẻ em (6 cái) | D24: TC 4 Sao | F24: =1190000/1.08*6 -> 6611111.1 | I24: 46259 | J24: Nhung
B25: Máy đo PH và máy quang đo clo dư (có kiểm định) | F25: 31850000 | I25: 46245 | J25: Ánh | N25: Bộ máy tính (CPU)+bộ nguồn cấp điện liên tục Cyber Power BU600E | O25: Bộ | P25: 1 | Q25: 15000000 | R25: 1 | S25: =Q25*R25 -> 15000000 | T25: Phòng PVHK
B26: Thanh nối cứng xử lý khẩn cấp D60 3M (6 cái) | F26: 9000000 | I26: 46252 | J26: Thịnh | N26: Máy hút bụi sạc pin cho tàu bay Makita | O26: cái | Q26: 4000000 | R26: 1 | S26: =Q26*R26 -> 4000000 | T26: Đội VSBX
B27: Chèn bánh xe | F27: =41999040/1.08 -> 38888000 | I27: 46237 | J27: Tân
B28: Máy scan 2 mặt Brother (Tổ ĐT-XDCB) | F28: =9900000/1.08 -> 9166666.7 | I28: 46279 | J28: Kiệt | M28: Đã mua | N28: Máy nén cao áp | O28: Bộ | Q28: 10000000 | R28: 1 | S28: =Q28*R28 -> 10000000 | T28: Đội VHTTBMĐ
B29: Máy lạnh phòng sếp Quân | F29: 23550000 | I29: 46283 | J29: Tân | N29: PHÒNG ĐIỀU HÀNH SÂN BAY
B30: Chèn bánh máy bay (4 cái) | F30: 5000000 | I30: 46310 | J30: Tân
I34: 46283 | J34: Tân | N34: PHÒNG ĐIỀU HÀNH SÂN BAY
N35: Bộ đàm cầm tay Motorola XiR P3688 | O35: Cái | Q35: 7500000 | R35: 3 | S35: =Q35*R35 -> 22500000 | T35: Đội ĐP-KHB: 01, Đội KN-PCCC: 02
B36: DANH MỤC CCDC CAC PHÒNG ĐỀ XUẤT CUỐI NĂM
B37: PHÒNG KTHT | H37: Y/c Giải trình | I37: GIẢI TRÌNH CỦA PHÒNG | N37: Bình chữa cháy gốc nước Orion Vinafoam Vloại 6kg | O37: Bình | Q37: 1900000 | R37: 15 | S37: =Q37*R37 -> 28500000
B38: Máy Scan | E38: 9166666.7 | G38: Số hóa hồ sơ Phòng KTHT | H38: Số lượng hiện có của Phòng ? | J38: Sếp ok cho mua | K38: 14000000 | N38: Bình chữa cháy bột MT 35kg | O38: Bình | Q38: 3750000 | R38: 8 | S38: =Q38*R38 -> 30000000 | T38: Thay thế binh Theo CV 4786/TCTCHKVN-ATKSCL
B39: Máy in màu HP Smart Tank 750 All-in-One (6UU47A) | G39: In bản vẽ phục vụ công việc Phòng KTHT | H39: Giải trình rõ tần suất và nhu cầu bắt buộc in màu bản vẽ. | I39: Chưa giải trình | K39: 10400000 | N39: Bình chữa cháy Bột (loại 8kg) | O39: Bình | Q39: 700000 | R39: 50 | S39: =Q39*R39 -> 35000000 | T39: Thay thế binh Theo CV 4786/TCTCHKVN-ATKSCL
B40: Máy hàn cáp quang COMWAY A33 và phụ kiện | G40: Xử lý đường truyền cáp quang khi bị sự cố | H40: Lưu ý giới hạn 30 triệu: Thiết bị nguyên khối vượt 30 triệu, không được xếp vào CCDC. Yêu cầu làm hồ sơ mua sắm TSCĐ. Nêu rõ tần suất sự cố đứt cáp để chứng minh sự cần thiết phải trang bị. | I40: Chưa giải trình | K40: 47000000 | N40: Bình chữa cháy cầm tay VINA FOAM (loại 6kg) | O40: Bình | Q40: 1000000 | R40: 20 | S40: =Q40*R40 -> 20000000 | T40: Mua mới trang bị cho các khu vực tập kết sạc xe điện, xách tay ga đi QT, QN, kho hàng
B41: Máy đo cáp quang OTDR, Model: TB-700-SCA | E41: 15000000 | G41: Đo kiểm vị trí cáp quang suy giảm tín hiệu | H41: Giải trình rõ tần suất và nhu cầu bắt buộc | I41: Chưa giải trình | N41: Bình chũa cháy CO2 loại 5kg | O41: Bình | Q41: 800000 | R41: 10 | S41: =Q41*R41 -> 8000000 | T41: Thay thế các bình hết hạn, cũ
B42: Dốc xe nâng điện | E42: 14000000
B43: PHÒNG PVMĐ | H43: Y/c Giải trình | I43: GIẢI TRÌNH CỦA PHÒNG | N43: Trang bị thuyền phao cứu hộ đối với cứu hộ đầm lầy khu vực CHK | O43: Chiếc | Q43: 10000000 | R43: 1 | S43: =Q43*R43 -> 10000000 | T43: Chỉ đạo về việc thực hiện đồng bộ trang bị đồng phục PCCC
B44: Tủ 12 ngăn | E44: 3500000 | G44: Đáp ứng yêu cầu ISAGO | J44: Sếp ok cho mua | N44: Chi sửa chữa CCDC | S44: 80000000 | T44: Thay pin cho các CCDC, thay Adapter, sửa chữa khác CCDC….
...

Sheet 627312
A2: STT | B2: Danh mục | C2: Mã khoản mục chi phí | D2: ĐƯỢC DUYỆT | E2: THỰC HIỆN NĂM TRƯỚC | F2: SỐ TIỀN ĐÃ/ ĐANG THỰC HIỆN | G2: CÒN LẠI/ TIẾN ĐỘ | H2: NGÀY | I2: NGƯỜI THỰC HIỆN | J2: MỤC LỤC
B3: Trang thiết bị văn phòng | C3: 627312 | D3: =VLOOKUP(C3,'TỔNG HỢP'!$C$4:$P$84,3,0) -> 73000000 | F3: =SUM(F4:F889) -> 0 | G3: =D3-F3 -> 73000000
B18: Máy scan HP Scanjet pro 3600 F1 | E18: 13990000 | H18: 45735 | I18: Văn Đức
B19: Màn hình máy tính Tổ vệ sinh | E19: 2290000 | H19: 45737 | I19: Phúc
B20: CPU NUC 11 pro thay thế máy đội CBTT&HDCX | E20: 8390000 | G20: Chưa BCMS | H20: 45737 | I20: Phúc
A21: 1 | B21: Máy in hóa đơn BIXOLON SRP-302 Trạm Thu Phí | E21: 5000000 | H21: 45737 | I21: Phúc
A22: 2 | B22: 2 Bảng từ trắng di động 1 mặt phục vụ huấn luyện | E22: =5292000/1.08 -> 4900000 | H22: 45737 | I22: Hải

Sheet 627313
A2: STT | B2: Danh mục | C2: Mã khoản mục chi phí | D2: ĐƯỢC DUYỆT | E2: BỔ SUNG | F2: SỐ TIỀN ĐÃ/ ĐANG THỰC HIỆN | G2: CÒN LẠI/ TIẾN ĐỘ | H2: QUY MÔ | I2: NGƯỜI THỰC HIỆN | J2: MỤC LỤC
B3: =VLOOKUP(C3,'TỔNG HỢP'!$C$4:$P$84,14,0) -> 0 | C3: 627313 | D3: =VLOOKUP(C3,'TỔNG HỢP'!$C$4:$P$84,3,0) -> 100000000 | F3: =SUM(F4:F889) -> 0
A21: 1
A22: 2

Sheet 627314
A2: STT | B2: Danh mục | C2: Mã khoản mục chi phí | D2: ĐƯỢC DUYỆT | E2: BỔ SUNG | F2: THỰC HIỆN | G2: CÒN LẠI/ TIẾN ĐỘ | H2: NGÀY | I2: NGƯỜI THỰC HIỆN | J2: MỤC LỤC
B3: Bàn ghế, tủ, quầy ,vật dụng khác | C3: 627314 | D3: =VLOOKUP(C3,'TỔNG HỢP'!$C$4:$P$84,3,0) -> 80000000 | F3: =SUM(F4:F885) -> 0 | G3: =D3-F3 -> 80000000
B13: Bàn lãnh đạo, tủ hồ sơ | E13: =4050000+3600000 -> 7650000 | H13: 45805 | I13: TrÂN
B14: Bàn phòng họp IMS (2 bàn ghép) | E14: 10369224 | H14: 45825 | I14: Kiệt
B15: Ghế phó giám đốc Bảy | E15: 3100000 | H15: 45834 | I15: TrÂN
A17: 1
A18: 2 | B18: Bàn họp phòng Phó giám đốc | E18: =7668000/1.08 -> 7100000
B19: Ghế cho quầy thủ tục | E19: 2808000 | H19: 45499 | I19: Tân

Sheet 627321
A2: STT | B2: Danh mục | C2: Mã khoản mục chi phí | D2: ĐƯỢC DUYỆT | E2: BỔ SUNG | F2: THỰC HIỆN | G2: CÒN LẠI/ TIẾN ĐỘ | H2: NGÀY | I2: NGƯỜI THỰC HIỆN | J2: MỤC LỤC
B3: Chi phí sửa chữa công cụ dụng cụ | C3: 627321 | D3: =VLOOKUP(C3,'TỔNG HỢP'!$C$4:$P$84,3,0) -> 196000000 | F3: =SUM(F4:F895) -> 157407.41 | G3: =D3-F3 -> 1.9584259e+08
B4: Mũi đục bê tông khu bay (1 cái) | F4: =170000/1.08 -> 157407.41 | H4: 46178 | I4: Ngân
B16: Sửa chữa máy xịt thuốc cỏ | E16: 1450000 | H16: 45712 | I16: Khoa
B17: Pin cho máy thổi 18V/6ah | E17: =2650000/1.1 -> 2409090.9 | H17: 45723
B18: Sửa chữa nguồn máy tính HP350W | E18: 450000 | H18: 45737 | I18: Phúc/Tân
B19: S/c CPU đội CBTT&HDCX
B20: Thay thế đầu máy hút bụi | E20: =520000/1.08 -> 481481.48 | H20: 45782 | I20: Thông/Tân
B21: Sửa chữa thay thế bơm nước ngưng cho máy lạnh phòng CACK | E21: 1300000 | H21: 45915 | I21: Tân
B22: Thay da ghế thay giày | E22: 1350000 | H22: 45950
B23: Drumn Brother | E23: 1800000 | H23: 45968 | I23: Duyên
B24: sửa chữa xe nâng tay kho hàng | E24: 2500000 | H24: 45978 | I24: Tân
B25: Sửa chữa máy tính | E25: 37145000 | H25: 45978 | I25: Tân
B26: Thay thế pin cho máy thổi Makita | E26: =5300000/1.08 -> 4907407.4 | H26: 45995 | I26: Tân
A27: 1 | B27: 2 Bơm thải nước điều hoà phòng CACK | E27: 2400000 | H27: 45345
A28: 2 | B28: Thay mâm lưỡi cắt cho máy cắt cỏ đẩy tay Honda HJR 216 | E28: 750000 | H28: 45428 | I28: Thanh Tân
A29: 3 | B29: Thay dây cao cáp cho máy xịt thuốc cỏ, máy rửa xe | E29: =22250000/1.08 -> 20601852 | H29: 45432 | I29: Thanh Tân
A30: 4 | B30: Sửa chữa máy thổi | E30: 366000 | H30: 45450 | I30: Nhung
A31: 5 | B31: Lưỡi cưa xích 18 inch | E31: 2750000 | H31: 45460 | I31: Thanh Tân
B32: Pin makita cho máy thổi | E32: =7650000/1.1 -> 6954545.5 | H32: 45489 | I32: Hải
B33: Thay bảng hướng dẫn lối đi | E33: 480000 | H33: 45474 | I33: Hải
B34: Mua sơn phản quang | E34: 800000 | H34: 45495 | I34: A Hoa
B35: Sửa chữa máy cắt kin loại Plasma và máy rửa áp lực ASADA | E35: 3100000 | H35: 45575 | I35: Công Đức

Sheet 627322
A2: STT | B2: Danh mục | C2: Mã khoản mục chi phí | D2: ĐƯỢC DUYỆT | E2: BỔ SUNG | F2: SỐ TIỀN ĐÃ/ ĐANG THỰC HIỆN | G2: CÒN LẠI/ TIẾN ĐỘ | H2: Ngày | I2: NGƯỜI THỰC HIỆN | J2: MỤC LỤC
B3: Chi phí sửa chữa công cụ dụng cụ (khối gián tiếp) | C3: 627322 | D3: =VLOOKUP(C3,'TỔNG HỢP'!$C$4:$P$84,3,0) -> 30000000 | F3: =SUM(F4:F896) -> 19887407 | G3: =D3-F3 -> 10112593
B4: Vật tư S/c máy lạnh cục bộ phòng Giám đốc | F4: =4550000/1.08 -> 4212963 | H4: 46057 | I4: Tân
B5: S/c Drum, đào kéo giấy, gạt mực | F5: =450000+220000+150000+90000 -> 910000 | H5: 46119 | I5: Duyên
B6: S/c máy hút bụi dùng pin (1 ống nối 2 pin) | F6: =5880000/1.08 -> 5444444.4 | H6: 46177 | I6: Nhung
B7: S/c máy photo văn phòng (Drum, gạt) | F7: 1950000 | H7: 46230 | I7: Trân
B8: S/c Drum, đào kéo giấy, gạt mực | F8: 7370000 | H8: 46269 | I8: Trân
B20: S/c máy in văn phòng quý 1 | E20: 1900000 | H20: 45741 | I20: Trân
B21: Pin AA sạc cho remote, thiết bị âm thanh | E21: 1520000 | H21: 45812 | I21: Công Đức
B22: Pin AA và pin AAA cho remote, thiết bị âm thanh | E22: 1330000 | H22: 45812 | I22: Tân
B23: Sửa chữa máy photo AOC | E23: 4650000 | H23: 45819 | I23: Trân
B24: Drum máy in | E24: 440000 | H24: 45859 | I24: Trân
B25: S/c máy in văn phòng T8/2025 | E25: 6290000 | H25: 45903 | I25: Trân
B26: S/c máy photo văn phòng | E26: 5950000 | H26: 45918 | I26: Trân
B27: S/c Drum Canon, sạc mực | E27: 550000 | H27: 45933 | I27: Trân
A28: 1 | B28: Sửa máy đếm tiền | E28: 540000
A29: 2 | B29: Thay thế vật tư cho máy scan canon DR F120 | E29: 1995000 | H29: 45573 | I29: Công Đức
B30: Bảo trì máy photo | E30: 960000 | G30: 45652 | H30: Trân

Sheet 62762101
A2: STT | B2: Danh mục | C2: Mã khoản mục chi phí | D2: ĐƯỢC DUYỆT | E2: BỔ SUNG | F2: THỰC HIỆN | G2: CÒN LẠI/ TIẾN ĐỘ | H2: NGÀY | I2: NGƯỜI THỰC HIỆN | J2: MỤC LỤC
B3: Sửa chữa nhà ga quốc nội | C3: 62762101 | D3: =VLOOKUP(C3,'TỔNG HỢP'!$C$4:$P$84,3,0) -> 260000000 | F3: =SUM(F4:F901) -> 140821619 | G3: =D3-F3 -> 119178381
B4: Sơn tường Nhà ga - VAECO | F4: 5494751 | H4: 46042 | I4: Kiệt
B5: Bản lề cửa phòng VIP | F5: 4650000 | H5: 46080 | I5: Ấn
B6: Nẹp che khe lún WC | F6: 2176800 | H6: 46100 | I6: Kiệt
B7: Sửa chữa ron gạch WC QN | F7: 45208800 | H7: 46129 | I7: Kiệt
B8: Sửa chữa gạch vỡ, dộp | F8: 42514548 | H8: 46132 | I8: Kiệt
B9: Foam trám khe | F9: 950000 | H9: 46169 | I9: Ấn
B10: Mở lối đi lan can Gate 8 | F10: 6260000 | H10: 46237 | I10: Kiệt
B11: Sửa khóa gate 8 | F11: 800000 | H11: 46282 | I11: Kiệt
B12: Mua gạch Granite (101,76m2) | F12: 32766720 | H12: 46315 | I12: Kiệt
A21: 1 | B21: Thay thế Vách kính tại trục 4J hành lang ga đi quốc tế | E21: 8754955 | H21: 45734 | I21: Kiệt
A22: 2 | B22: Sửa chữa 40m2 gạch | E22: 23091123 | H22: 45828 | I22: Tùng
A23: 3 | B23: Thuê cẩu và gia cố trần nhôm | E23: 5407624 | H23: 45828 | I23: Tùng
A24: 4 | B24: Ron chặn kính, lan can thang máy | E24: 14645000 | H24: 45841 | I24: Kiệt
A25: 5 | B25: Decal lấy sáng xanh | E25: 3579840 | H25: 45926 | I25: Kiệt
A26: 6 | B26: Thay thế các kính WC | E26: 81144000 | H26: 45986 | I26: Hà
A27: 7 | B27: Sơn tường tại Nhà ga hành khách | E27: =46745892/1.08 -> 43283233 | I27: Tùng
A28: 8 | B28: Trần thay thế 300m2 | D28: 300 | E28: 84440398 | H28: 45982 | I28: Tùng
A29: 9 | B29: Dự kiến mua Vật tư Thảm khu vực ANHK | D29: 110 | E29: 85860000 | H29: 46008 | I29: Ấn
A33: 1 | B33: Cửa lùa chống mất áp cầu thang | E33: 6850000 | H33: 45416 | I33: Kiệt
A34: 2 | B34: Vật tư chèn bị chỗ tiếp giáp giữa các đường ống cứu hỏa, máng cáp điện, ống lạnh thông qua các trục điện phòng AHU phòng UPS phòng COM | E34: 25152000 | H34: 45587 | I34: Tân
A35: 3 | B35: Sửa chữa lát gạch và các hạng mục vật kiến trúc khác | E35: 206000000 | H35: 45611 | I35: Kiệt
A36: 4 | B36: Dán Decal chống nóng mái kính nhà ga hành khách | E36: 40000000 | H36: 45606 | I36: Kiệt

Sheet 62762103
A2: STT | B2: Danh mục | C2: Mã khoản mục chi phí | D2: ĐƯỢC DUYỆT | E2: BỔ SUNG | F2: THỰC HIỆN | G2: CÒN LẠI/ TIẾN ĐỘ | H2: NGÀY | I2: NGƯỜI THỰC HIỆN | J2: MỤC LỤC
B3: =VLOOKUP(C3,'TỔNG HỢP'!$C$4:$P$84,14,0) -> Sửa chữa bến bãi ô tô, sân đường | C3: 62762103 | D3: =VLOOKUP(C3,'TỔNG HỢP'!$C$4:$P$84,3,0) -> 110000000 | F3: =SUM(F4:F889) -> 62382513 | G3: =D3-F3 -> 47617487
B4: SC bến bãi ô tô sân đường 2026 | F4: 56481481 | H4: 46150 | I4: Dũng
B5: Sửa chữa nắp đan (bù lún carboncor) | F5: =1234715/1.08 -> 1143254.6 | H5: 46161 | I5: Kiệt
B6: Trụ phân làn và vật tư bulong | F6: =5138400/1.08 -> 4757777.8 | H6: 46175 | I6: Ấn
B20: Sơn bảo dưỡng 1 phần sơn tín hiệu sân đậu ô tô khách | E20: 478000000 | H20: 45758 | I20: Khôi
A21: 1 | B21: Sửa chữa nội dung biển báo giao thông | E21: 972000 | H21: 45418 | I21: Kiệt
A22: 2 | B22: Sửa chữa lắp đặt biển báo giao thông nội bộ và sơn ô cảnh báo tủ PCCC nhà xe máy | E22: 6800000 | H22: 45491 | I22: Kiệt
B23: Biển báo giao thông nội bộ | E23: 7480000 | H23: 45510 | I23: Kiệt
E24: 59000000

Sheet 62762104
A2: STT | B2: Danh mục | C2: Mã khoản mục chi phí | D2: ĐƯỢC DUYỆT | E2: BỔ SUNG | F2: THỰC HIỆN | G2: CÒN LẠI/ TIẾN ĐỘ | H2: QUY MÔ | I2: NGƯỜI THỰC HIỆN | J2: MỤC LỤC
B3: Chi phí sửa chữa mương thoát nước | C3: 62762104 | D3: =VLOOKUP(C3,'TỔNG HỢP'!$C$4:$P$84,3,0) -> 69000000 | F3: =SUM(F4:F889) -> 11090741 | G3: =D3-F3 -> 57909259
B4: Ống thoát nước Trạm thu phí | D4: =3500000/1.08 -> 3240740.7 | F4: =3500000/1.08 -> 3240740.7 | H4: 46119 | I4: Dũng
B5: Tấm đan nhà xe ngoại trường | F5: 7850000 | H5: 46275 | I5: Kiệt
B20: Sửa chữa nắp cống | E20: 98000000
A21: 1 | B21: Sửa chữa nắp đan | E21: 49880000 | H21: 45391 | I21: Kiệt
A22: 2

Sheet 62762105
A2: STT | B2: Danh mục | C2: Mã khoản mục chi phí | D2: ĐƯỢC DUYỆT | E2: BỔ SUNG | F2: SỐ TIỀN ĐÃ/ ĐANG THỰC HIỆN | G2: CÒN LẠI/ TIẾN ĐỘ | H2: QUY MÔ | I2: NGƯỜI THỰC HIỆN | J2: MỤC LỤC
B3: Chi phí cắt cỏ, nạo vét mương thoát nước | C3: 62762105 | D3: =VLOOKUP(C3,'TỔNG HỢP'!$C$4:$P$84,3,0) -> 30000000 | F3: =SUM(F4:F889) -> 0 | G3: =D3-F3 -> 30000000
A21: 1 | E21: 38000000
A22: 2

Sheet 62762106
A2: STT | B2: Danh mục | C2: Mã khoản mục chi phí | D2: ĐƯỢC DUYỆT | E2: BỔ SUNG | F2: SỐ TIỀN ĐÃ/ ĐANG THỰC HIỆN | G2: CÒN LẠI/ TIẾN ĐỘ | H2: NGÀY | I2: NGƯỜI THỰC HIỆN | J2: MỤC LỤC
B3: Sửa chữa sân đậu | C3: 62762106 | D3: =VLOOKUP(C3,'TỔNG HỢP'!$C$4:$P$84,3,0) -> 420000000 | F3: =SUM(F4:F889) -> 0 | G3: =D3-F3 -> 420000000
B17: Vật tư bảo dưỡng các hố neo sân đỗ tàu bay | E17: 4575000 | H17: 45789
B18: Bù vênh đường công vụ | E18: 9354600 | H18: 45847 | I18: Kiệt
B19: Sơn bảo dưỡng | E19: 474647126
A21: 1
A22: 2 | B22: Vật tư bảo dưỡng các hố neo tàu | E22: =3300000/1.08 -> 3055555.6 | H22: 45454 | I22: Tân

Sheet 62762107
A2: STT | B2: Danh mục | C2: Mã khoản mục chi phí | D2: ĐƯỢC DUYỆT | E2: BỔ SUNG | F2: SỐ TIỀN ĐÃ/ ĐANG THỰC HIỆN | G2: CÒN LẠI/ TIẾN ĐỘ | H2: QUY MÔ | I2: NGƯỜI THỰC HIỆN | J2: MỤC LỤC
B3: =VLOOKUP(C3,'TỔNG HỢP'!$C$4:$P$84,14,0) -> Sửa chữa hàng rào | C3: 62762107 | D3: =VLOOKUP(C3,'TỔNG HỢP'!$C$4:$P$84,3,0) -> 60000000 | F3: =SUM(F4:F889) -> 54788503 | G3: =D3-F3 -> 5211497.2
B4: Sửa chữa hàng rào Airside Landside | F4: =59171583/1.08 -> 54788503 | H4: 46132 | I4: Tùng
A21: 1
A22: 2 | B22: Bảo dưỡng hàng rào tường (Đoạn 1 từ Nhà ga hành khách đến cổng rào cổng 1; Đoạn 2 từ Nhà xe ngoại trường đến hàng rào lưới B40) và Bảo dưỡng cổng rào cổng 1” | E22: 77002619 | I22: Kiệt

Sheet 62762188
A2: STT | B2: Danh mục | C2: Mã khoản mục chi phí | D2: ĐƯỢC DUYỆT | E2: BỔ SUNG | F2: SỐ TIỀN ĐÃ/ ĐANG THỰC HIỆN | G2: CÒN LẠI/ TIẾN ĐỘ | H2: NGÀY | I2: NGƯỜI THỰC HIỆN | J2: MỤC LỤC
B3: Sửa chữa nhà cửa, vật kiến trúc khác | C3: 62762188 | D3: =VLOOKUP(C3,'TỔNG HỢP'!$C$4:$P$84,3,0) -> 90000000 | F3: =SUM(F4:F889) -> 69293904 | G3: =D3-F3 -> 20706096
F4: 4650000
B5: Bảo dưỡng, sửa chữa chống thấm hố van bể chứa nhiên liệu tại Nhà xe ngoại trường | H5: 46258 | I5: Kiệt | J5: 38800000
B6: S/c vỉa hè nhà xe ngoại trường | F6: 11043904 | H6: 46268 | I6: Dũng
B7: Lắp đặt cầu nâng điện phía trước kho hàng | F7: 14000000 | H7: 46303 | I7: Văn Đức
B8: Bảo dưỡng, sửa chữa chống thấm hố van bể chứa nhiên liệu tại Nhà xe ngoại trường | F8: 39600000 | H8: 46315 | I8: Kiệt
B16: Lắp đặt, thay thế cửa kéo Đài Loan tại khu vực xử lý hàng hóa | E16: 8827020 | H16: 45706 | I16: Kiệt
B17: Thay thế ván bị mục | E17: 27000000
B18: Sửa chữa mái đón | E18: 50000000
A21: 1 | B21: Bảo dưỡng khu vực Nhà xe ngoại trường | E21: 205000000
A22: 2

Sheet 62762189
A2: STT | B2: Danh mục | C2: Mã khoản mục chi phí | D2: ĐƯỢC DUYỆT | E2: BỔ SUNG | F2: THỰC HIỆN | G2: CÒN LẠI/ TIẾN ĐỘ | H2: Ngày | I2: NGƯỜI THỰC HIỆN | J2: MỤC LỤC
B3: Sửa chữa nhà cửa, vật kiến trúc khác (khối gián tiếp) | C3: 62762189 | D3: =VLOOKUP(C3,'TỔNG HỢP'!$C$4:$P$84,3,0) -> 110000000 | F3: =SUM(F4:F889) -> 19774400 | G3: =D3-F3 -> 90225600
B4: Bảng tên phòng họp phòng điều hành sân bay | F4: 490000 | H4: 46126 | I4: Nhung
B5: Các cửa nhôm | F5: 19284400 | H5: 46276 | I5: Kiệt
B16: Sửa chữa cáp chằng néo kết cấu mái tôn khu vực kho hàng hóa | E16: 5150000 | H16: 45786 | I16: Tân
B17: Thay thảm, thay kính, ổ khóa phòng trực | E17: 35560560 | H17: 45804
B18: Dời cửa, dán decal | H18: 45810 | I18: Kiệt
A21: 1 | B21: Bảng tên văn phòng, 6 cái | E21: 2970000 | H21: 45416 | I21: Minh
B22: Vách ngăn chống ẩm phòng Giám đốc | E22: 8640000 | H22: 45637 | I22: Trân

Sheet 62762201
A1: 0
A2: STT | B2: Danh mục | C2: Mã khoản mục chi phí | D2: ĐƯỢC DUYỆT | E2: BỔ SUNG | F2: THỰC HIỆN | G2: CÒN LẠI/ TIẾN ĐỘ | H2: Ngày thực hiện | I2: NGƯỜI THỰC HIỆN | J2: MỤC LỤC | K2: STT | L2: NỘI DUNG | M2: ĐVT | N2: SL | O2: ĐƠN GIÁ | P2: THÀNH TIỀN | Q2: GHI CHÚ
B3: Sửa chữa hệ thống băng chuyền | C3: 62762201 | D3: =VLOOKUP(C3,'TỔNG HỢP'!$C$4:$P$84,3,0) -> 920000000 | F3: =SUM(F4:F903) -> 293060000 | G3: =D3-F3 -> 626940000 | K3: 1 | L3: Băng tải các loại | M3: Mét | N3: 164 | O3: 1500000 | P3: 246000000 | Q3: đoạn tapi A1, A9, A12, A15, B1, B2, B9, B12, B13, B15
B4: Thay thế bánh xe chịu lực dưới băng chuyền trả hành lý QN 4 | F4: 4400000 | H4: 46150 | I4: Tân
B5: Thay thế động có Interroll quầy cân 13 | F5: 56000000 | H5: 46207 | I5: Tân
B6: Thay thế bánh xe chịu lực dưới băng chuyền trả hành lý QN 4 (35 bộ) | F6: 7700000 | H6: 46233 | I6: Tân
B7: Thay thế Băng tải B1, B16 băng chuyền ga đi QN | F7: 161460000 | H7: 46258 | I7: Tân
B8: Biến tần băng chuyền B2 | F8: 63500000 | H8: 46315 | I8: Tân
B19: Sửa chữa các màn hình điều khiển biến tần và biến tần hệ thống băng chuyền đi | E19: 114500000 | G19: 114500000 | H19: 45698 | I19: Lộc/Tân
B20: Bạc đạn rulo băng chuyền B12 Quốc nội | E20: 1300000 | G20: 1300000 | H20: 45695 | I20: Khoa/Tân
B21: Gối đỡ SKF | E21: 1850000
B22: Vật tư sửa chữa thay thế cảm biến từ băng chuyền trả hành lý đến số 02 và 2 cảm biến quang băng chuyền B11, 12 | E22: 11700000 | H22: 45761 | I22: Tân
B23: Động cơ Interroll quầy cân số 14 | E23: 54500000 | G23: 54500000 | H23: 45813 | I23: Lộc/Tân
